Traceback (most recent call last):
  File "C:\Users\henri\Documents\Kod\my_project\venv\lib\site-packages\urllib3\connection.py", line 159, in _new_conn
    conn = connection.create_connection(
  File "C:\Users\henri\Documents\Kod\my_project\venv\lib\site-packages\urllib3\util\connection.py", line 84, in create_connection
    raise err
  File "C:\Users\henri\Documents\Kod\my_project\venv\lib\site-packages\urllib3\util\connection.py", line 74, in create_connection
    sock.connect(sa)
TimeoutError: [WinError 10060] Anslutningsförsöket misslyckades eftersom den anslutna datorn inte svarade inom en viss tid eller på grund av att den etablerade anslutningen till värddatorn inte längre fungerar
During handling of the above exception, another exception occurred:
Traceback (most recent call last):
  File "C:\Users\henri\Documents\Kod\my_project\venv\lib\site-packages\urllib3\connectionpool.py", line 670, in urlopen
    httplib_response = self._make_request(
  File "C:\Users\henri\Documents\Kod\my_project\venv\lib\site-packages\urllib3\connectionpool.py", line 392, in _make_request
    conn.request(method, url, **httplib_request_kw)
  File "C:\Users\henri\AppData\Local\Programs\Python\Python38-32\lib\http\client.py", line 1255, in request
    self._send_request(method, url, body, headers, encode_chunked)
  File "C:\Users\henri\AppData\Local\Programs\Python\Python38-32\lib\http\client.py", line 1301, in _send_request
    self.endheaders(body, encode_chunked=encode_chunked)
  File "C:\Users\henri\AppData\Local\Programs\Python\Python38-32\lib\http\client.py", line 1250, in endheaders
    self._send_output(message_body, encode_chunked=encode_chunked)
  File "C:\Users\henri\AppData\Local\Programs\Python\Python38-32\lib\http\client.py", line 1010, in _send_output
    self.send(msg)
  File "C:\Users\henri\AppData\Local\Programs\Python\Python38-32\lib\http\client.py", line 950, in send
    self.connect()
  File "C:\Users\henri\Documents\Kod\my_project\venv\lib\site-packages\urllib3\connection.py", line 187, in connect
    conn = self._new_conn()
  File "C:\Users\henri\Documents\Kod\my_project\venv\lib\site-packages\urllib3\connection.py", line 171, in _new_conn
    raise NewConnectionError(
urllib3.exceptions.NewConnectionError: <urllib3.connection.HTTPConnection object at 0x0E388BB0>: Failed to establish a new connection: [WinError 10060] Anslutningsförsöket misslyckades eftersom den anslutna datorn inte svarade inom en viss tid eller på grund av att den etablerade anslutningen till värddatorn inte längre fungerar
During handling of the above exception, another exception occurred:
Traceback (most recent call last):
  File "C:\Users\henri\Documents\Kod\my_project\venv\lib\site-packages\requests\adapters.py", line 439, in send
    resp = conn.urlopen(
  File "C:\Users\henri\Documents\Kod\my_project\venv\lib\site-packages\urllib3\connectionpool.py", line 726, in urlopen
    retries = retries.increment(
  File "C:\Users\henri\Documents\Kod\my_project\venv\lib\site-packages\urllib3\util\retry.py", line 439, in increment
    raise MaxRetryError(_pool, url, error or ResponseError(cause))
urllib3.exceptions.MaxRetryError: HTTPConnectionPool(host='api.luftdaten.info', port=80): Max retries exceeded with url: /v1/sensor/50643/ (Caused by NewConnectionError('<urllib3.connection.HTTPConnection object at 0x0E388BB0>: Failed to establish a new connection: [WinError 10060] Anslutningsförsöket misslyckades eftersom den anslutna datorn inte svarade inom en viss tid eller på grund av att den etablerade anslutningen till värddatorn inte längre fungerar'))
During handling of the above exception, another exception occurred:
Traceback (most recent call last):
  File "<input>", line 1, in <module>
  File "C:\Users\henri\AppData\Local\JetBrains\Toolbox\apps\PyCharm-P\ch-0\202.7319.64\plugins\python\helpers\pydev\_pydev_bundle\pydev_umd.py", line 197, in runfile
    pydev_imports.execfile(filename, global_vars, local_vars)  # execute the script
  File "C:\Users\henri\AppData\Local\JetBrains\Toolbox\apps\PyCharm-P\ch-0\202.7319.64\plugins\python\helpers\pydev\_pydev_imps\_pydev_execfile.py", line 18, in execfile
    exec(compile(contents+"\n", file, 'exec'), glob, loc)
  File "C:/Users/henri/Documents/Kod/my_project/main.py", line 50, in <module>
    main()
  File "C:/Users/henri/Documents/Kod/my_project/main.py", line 45, in main
    api_request()
  File "C:/Users/henri/Documents/Kod/my_project/main.py", line 25, in api_request
    response = requests.get("http://api.luftdaten.info/v1/sensor/50643/")
  File "C:\Users\henri\Documents\Kod\my_project\venv\lib\site-packages\requests\api.py", line 76, in get
    return request('get', url, params=params, **kwargs)
  File "C:\Users\henri\Documents\Kod\my_project\venv\lib\site-packages\requests\api.py", line 61, in request
    return session.request(method=method, url=url, **kwargs)
  File "C:\Users\henri\Documents\Kod\my_project\venv\lib\site-packages\requests\sessions.py", line 530, in request
    resp = self.send(prep, **send_kwargs)
  File "C:\Users\henri\Documents\Kod\my_project\venv\lib\site-packages\requests\sessions.py", line 643, in send
    r = adapter.send(request, **kwargs)
  File "C:\Users\henri\Documents\Kod\my_project\venv\lib\site-packages\requests\adapters.py", line 516, in send
    raise ConnectionError(e, request=request)
requests.exceptions.ConnectionError: HTTPConnectionPool(host='api.luftdaten.info', port=80): Max retries exceeded with url: /v1/sensor/50643/ (Caused by NewConnectionError('<urllib3.connection.HTTPConnection object at 0x0E388BB0>: Failed to establish a new connection: [WinError 10060] Anslutningsförsöket misslyckades eftersom den anslutna datorn inte svarade inom en viss tid eller på grund av att den etablerade anslutningen till värddatorn inte längre fungerar'))